[2023-06-19T06:14:33.788+0000] {logging_mixin.py:149} WARNING - /home/***/.local/lib/python3.7/site-packages/***/utils/sqlalchemy.py:124 DeprecationWarning: The sql_alchemy_conn option in [core] has been moved to the sql_alchemy_conn option in [database] - the old setting has been used, but please update your config.
[2023-06-19T06:14:33.824+0000] {taskinstance.py:1103} INFO - Dependencies all met for dep_context=non-requeueable deps ti=<TaskInstance: data_ingestion_gcs_dag.local_to_gcs scheduled__2023-06-19T05:00:00+00:00 [queued]>
[2023-06-19T06:14:33.847+0000] {taskinstance.py:1103} INFO - Dependencies all met for dep_context=requeueable deps ti=<TaskInstance: data_ingestion_gcs_dag.local_to_gcs scheduled__2023-06-19T05:00:00+00:00 [queued]>
[2023-06-19T06:14:33.848+0000] {taskinstance.py:1308} INFO - Starting attempt 1 of 3
[2023-06-19T06:14:33.874+0000] {taskinstance.py:1327} INFO - Executing <Task(LocalFilesystemToGCSOperator): local_to_gcs> on 2023-06-19 05:00:00+00:00
[2023-06-19T06:14:33.888+0000] {standard_task_runner.py:57} INFO - Started process 1577 to run task
[2023-06-19T06:14:33.897+0000] {standard_task_runner.py:84} INFO - Running: ['***', 'tasks', 'run', 'data_ingestion_gcs_dag', 'local_to_gcs', 'scheduled__2023-06-19T05:00:00+00:00', '--job-id', '5', '--raw', '--subdir', 'DAGS_FOLDER/stock_data_to_gcp.py', '--cfg-path', '/tmp/tmpah0v0kwt']
[2023-06-19T06:14:33.901+0000] {standard_task_runner.py:85} INFO - Job 5: Subtask local_to_gcs
[2023-06-19T06:14:33.934+0000] {logging_mixin.py:149} WARNING - /home/***/.local/lib/python3.7/site-packages/***/settings.py:195 DeprecationWarning: The sql_alchemy_conn option in [core] has been moved to the sql_alchemy_conn option in [database] - the old setting has been used, but please update your config.
[2023-06-19T06:14:34.010+0000] {task_command.py:410} INFO - Running <TaskInstance: data_ingestion_gcs_dag.local_to_gcs scheduled__2023-06-19T05:00:00+00:00 [running]> on host 35a338de92cb
[2023-06-19T06:14:34.036+0000] {logging_mixin.py:149} WARNING - /home/***/.local/lib/python3.7/site-packages/***/utils/sqlalchemy.py:124 DeprecationWarning: The sql_alchemy_conn option in [core] has been moved to the sql_alchemy_conn option in [database] - the old setting has been used, but please update your config.
[2023-06-19T06:14:34.570+0000] {taskinstance.py:1547} INFO - Exporting env vars: AIRFLOW_CTX_DAG_EMAIL='***@***.com' AIRFLOW_CTX_DAG_OWNER='***' AIRFLOW_CTX_DAG_ID='data_ingestion_gcs_dag' AIRFLOW_CTX_TASK_ID='local_to_gcs' AIRFLOW_CTX_EXECUTION_DATE='2023-06-19T05:00:00+00:00' AIRFLOW_CTX_TRY_NUMBER='1' AIRFLOW_CTX_DAG_RUN_ID='scheduled__2023-06-19T05:00:00+00:00'
[2023-06-19T06:14:34.572+0000] {crypto.py:83} WARNING - empty cryptography key - values will not be stored encrypted.
[2023-06-19T06:14:34.572+0000] {base.py:73} INFO - Using connection ID 'google_cloud_default' for task execution.
[2023-06-19T06:14:34.574+0000] {taskinstance.py:1824} ERROR - Task failed with exception
Traceback (most recent call last):
  File "/home/airflow/.local/lib/python3.7/site-packages/airflow/providers/google/cloud/transfers/local_to_gcs.py", line 116, in execute
    gzip=self.gzip,
  File "/home/airflow/.local/lib/python3.7/site-packages/airflow/providers/google/cloud/hooks/gcs.py", line 508, in upload
    client = self.get_conn()
  File "/home/airflow/.local/lib/python3.7/site-packages/airflow/providers/google/cloud/hooks/gcs.py", line 172, in get_conn
    credentials=self.get_credentials(), client_info=CLIENT_INFO, project=self.project_id
  File "/home/airflow/.local/lib/python3.7/site-packages/airflow/providers/google/common/hooks/base_google.py", line 281, in get_credentials
    credentials, _ = self.get_credentials_and_project_id()
  File "/home/airflow/.local/lib/python3.7/site-packages/airflow/providers/google/common/hooks/base_google.py", line 267, in get_credentials_and_project_id
    delegates=delegates,
  File "/home/airflow/.local/lib/python3.7/site-packages/airflow/providers/google/cloud/utils/credentials_provider.py", line 332, in get_credentials_and_project_id
    return _CredentialProvider(*args, **kwargs).get_credentials_and_project()
  File "/home/airflow/.local/lib/python3.7/site-packages/airflow/providers/google/cloud/utils/credentials_provider.py", line 231, in get_credentials_and_project
    credentials, project_id = self._get_credentials_using_key_path()
  File "/home/airflow/.local/lib/python3.7/site-packages/airflow/providers/google/cloud/utils/credentials_provider.py", line 281, in _get_credentials_using_key_path
    self.key_path, scopes=self.scopes
  File "/home/airflow/.local/lib/python3.7/site-packages/google/oauth2/service_account.py", line 256, in from_service_account_file
    filename, require=["client_email", "token_uri"]
  File "/home/airflow/.local/lib/python3.7/site-packages/google/auth/_service_account_info.py", line 80, in from_filename
    with io.open(filename, "r", encoding="utf-8") as json_file:
FileNotFoundError: [Errno 2] No such file or directory: '/.google/credentials/google_credentials.json'
[2023-06-19T06:14:34.590+0000] {taskinstance.py:1350} INFO - Marking task as UP_FOR_RETRY. dag_id=data_ingestion_gcs_dag, task_id=local_to_gcs, execution_date=20230619T050000, start_date=20230619T061433, end_date=20230619T061434
[2023-06-19T06:14:34.616+0000] {standard_task_runner.py:109} ERROR - Failed to execute job 5 for task local_to_gcs ([Errno 2] No such file or directory: '/.google/credentials/google_credentials.json'; 1577)
[2023-06-19T06:14:34.672+0000] {local_task_job_runner.py:225} INFO - Task exited with return code 1
[2023-06-19T06:14:34.744+0000] {taskinstance.py:2651} INFO - 0 downstream tasks scheduled from follow-on schedule check
