[2023-06-19T06:19:37.015+0000] {logging_mixin.py:149} WARNING - /home/***/.local/lib/python3.7/site-packages/***/utils/sqlalchemy.py:124 DeprecationWarning: The sql_alchemy_conn option in [core] has been moved to the sql_alchemy_conn option in [database] - the old setting has been used, but please update your config.
[2023-06-19T06:19:37.037+0000] {taskinstance.py:1103} INFO - Dependencies all met for dep_context=non-requeueable deps ti=<TaskInstance: data_ingestion_gcs_dag.local_to_gcs scheduled__2023-06-19T05:00:00+00:00 [queued]>
[2023-06-19T06:19:37.051+0000] {taskinstance.py:1103} INFO - Dependencies all met for dep_context=requeueable deps ti=<TaskInstance: data_ingestion_gcs_dag.local_to_gcs scheduled__2023-06-19T05:00:00+00:00 [queued]>
[2023-06-19T06:19:37.052+0000] {taskinstance.py:1308} INFO - Starting attempt 2 of 3
[2023-06-19T06:19:37.074+0000] {taskinstance.py:1327} INFO - Executing <Task(LocalFilesystemToGCSOperator): local_to_gcs> on 2023-06-19 05:00:00+00:00
[2023-06-19T06:19:37.085+0000] {standard_task_runner.py:57} INFO - Started process 1775 to run task
[2023-06-19T06:19:37.092+0000] {standard_task_runner.py:84} INFO - Running: ['***', 'tasks', 'run', 'data_ingestion_gcs_dag', 'local_to_gcs', 'scheduled__2023-06-19T05:00:00+00:00', '--job-id', '6', '--raw', '--subdir', 'DAGS_FOLDER/stock_data_to_gcp.py', '--cfg-path', '/tmp/tmpvi35yuo6']
[2023-06-19T06:19:37.096+0000] {standard_task_runner.py:85} INFO - Job 6: Subtask local_to_gcs
[2023-06-19T06:19:37.121+0000] {logging_mixin.py:149} WARNING - /home/***/.local/lib/python3.7/site-packages/***/settings.py:195 DeprecationWarning: The sql_alchemy_conn option in [core] has been moved to the sql_alchemy_conn option in [database] - the old setting has been used, but please update your config.
[2023-06-19T06:19:37.183+0000] {task_command.py:410} INFO - Running <TaskInstance: data_ingestion_gcs_dag.local_to_gcs scheduled__2023-06-19T05:00:00+00:00 [running]> on host 35a338de92cb
[2023-06-19T06:19:37.202+0000] {logging_mixin.py:149} WARNING - /home/***/.local/lib/python3.7/site-packages/***/utils/sqlalchemy.py:124 DeprecationWarning: The sql_alchemy_conn option in [core] has been moved to the sql_alchemy_conn option in [database] - the old setting has been used, but please update your config.
[2023-06-19T06:19:37.602+0000] {taskinstance.py:1547} INFO - Exporting env vars: AIRFLOW_CTX_DAG_EMAIL='***@***.com' AIRFLOW_CTX_DAG_OWNER='***' AIRFLOW_CTX_DAG_ID='data_ingestion_gcs_dag' AIRFLOW_CTX_TASK_ID='local_to_gcs' AIRFLOW_CTX_EXECUTION_DATE='2023-06-19T05:00:00+00:00' AIRFLOW_CTX_TRY_NUMBER='2' AIRFLOW_CTX_DAG_RUN_ID='scheduled__2023-06-19T05:00:00+00:00'
[2023-06-19T06:19:37.605+0000] {crypto.py:83} WARNING - empty cryptography key - values will not be stored encrypted.
[2023-06-19T06:19:37.606+0000] {base.py:73} INFO - Using connection ID 'google_cloud_default' for task execution.
[2023-06-19T06:19:37.771+0000] {gcs.py:499} ERROR - Upload attempt of object: raw/stock_data.csv from raw/stock_data.csv has failed. Attempt: 1, max 1.
[2023-06-19T06:19:37.771+0000] {taskinstance.py:1824} ERROR - Task failed with exception
Traceback (most recent call last):
  File "/home/airflow/.local/lib/python3.7/site-packages/google/cloud/storage/blob.py", line 2553, in upload_from_file
    retry=retry,
  File "/home/airflow/.local/lib/python3.7/site-packages/google/cloud/storage/blob.py", line 2368, in _do_upload
    retry=retry,
  File "/home/airflow/.local/lib/python3.7/site-packages/google/cloud/storage/blob.py", line 1891, in _do_multipart_upload
    transport, data, object_metadata, content_type, timeout=timeout
  File "/home/airflow/.local/lib/python3.7/site-packages/google/resumable_media/requests/upload.py", line 154, in transmit
    retriable_request, self._get_status_code, self._retry_strategy
  File "/home/airflow/.local/lib/python3.7/site-packages/google/resumable_media/requests/_request_helpers.py", line 155, in wait_and_retry
    response = func()
  File "/home/airflow/.local/lib/python3.7/site-packages/google/resumable_media/requests/upload.py", line 149, in retriable_request
    self._process_response(result)
  File "/home/airflow/.local/lib/python3.7/site-packages/google/resumable_media/_upload.py", line 114, in _process_response
    _helpers.require_status_code(response, (http.client.OK,), self._get_status_code)
  File "/home/airflow/.local/lib/python3.7/site-packages/google/resumable_media/_helpers.py", line 113, in require_status_code
    *status_codes
google.resumable_media.common.InvalidResponse: ('Request failed with status code', 403, 'Expected one of', <HTTPStatus.OK: 200>)

During handling of the above exception, another exception occurred:

Traceback (most recent call last):
  File "/home/airflow/.local/lib/python3.7/site-packages/airflow/providers/google/cloud/transfers/local_to_gcs.py", line 116, in execute
    gzip=self.gzip,
  File "/home/airflow/.local/lib/python3.7/site-packages/airflow/providers/google/cloud/hooks/gcs.py", line 533, in upload
    partial(blob.upload_from_filename, filename=filename, content_type=mime_type, timeout=timeout)
  File "/home/airflow/.local/lib/python3.7/site-packages/airflow/providers/google/cloud/hooks/gcs.py", line 501, in _call_with_retry
    raise e
  File "/home/airflow/.local/lib/python3.7/site-packages/airflow/providers/google/cloud/hooks/gcs.py", line 490, in _call_with_retry
    f()
  File "/home/airflow/.local/lib/python3.7/site-packages/google/cloud/storage/blob.py", line 2697, in upload_from_filename
    retry=retry,
  File "/home/airflow/.local/lib/python3.7/site-packages/google/cloud/storage/blob.py", line 2557, in upload_from_file
    _raise_from_invalid_response(exc)
  File "/home/airflow/.local/lib/python3.7/site-packages/google/cloud/storage/blob.py", line 4369, in _raise_from_invalid_response
    raise exceptions.from_http_status(response.status_code, message, response=response)
google.api_core.exceptions.Forbidden: 403 POST https://storage.googleapis.com/upload/storage/v1/b/airflow_1234/o?uploadType=multipart: {
  "error": {
    "code": 403,
    "message": "airflow-project@cedar-shard-385120.iam.gserviceaccount.com does not have storage.objects.create access to the Google Cloud Storage object. Permission 'storage.objects.create' denied on resource (or it may not exist).",
    "errors": [
      {
        "message": "airflow-project@cedar-shard-385120.iam.gserviceaccount.com does not have storage.objects.create access to the Google Cloud Storage object. Permission 'storage.objects.create' denied on resource (or it may not exist).",
        "domain": "global",
        "reason": "forbidden"
      }
    ]
  }
}
: ('Request failed with status code', 403, 'Expected one of', <HTTPStatus.OK: 200>)
[2023-06-19T06:19:37.788+0000] {taskinstance.py:1350} INFO - Marking task as UP_FOR_RETRY. dag_id=data_ingestion_gcs_dag, task_id=local_to_gcs, execution_date=20230619T050000, start_date=20230619T061937, end_date=20230619T061937
[2023-06-19T06:19:37.804+0000] {standard_task_runner.py:109} ERROR - Failed to execute job 6 for task local_to_gcs (403 POST https://storage.googleapis.com/upload/storage/v1/b/airflow_1234/o?uploadType=multipart: {
  "error": {
    "code": 403,
    "message": "airflow-project@cedar-shard-385120.iam.gserviceaccount.com does not have storage.objects.create access to the Google Cloud Storage object. Permission 'storage.objects.create' denied on resource (or it may not exist).",
    "errors": [
      {
        "message": "airflow-project@cedar-shard-385120.iam.gserviceaccount.com does not have storage.objects.create access to the Google Cloud Storage object. Permission 'storage.objects.create' denied on resource (or it may not exist).",
        "domain": "global",
        "reason": "forbidden"
      }
    ]
  }
}
: ('Request failed with status code', 403, 'Expected one of', <HTTPStatus.OK: 200>); 1775)
[2023-06-19T06:19:37.864+0000] {local_task_job_runner.py:225} INFO - Task exited with return code 1
[2023-06-19T06:19:37.912+0000] {taskinstance.py:2651} INFO - 0 downstream tasks scheduled from follow-on schedule check
