[2023-06-18T06:07:01.001+0000] {taskinstance.py:1103} INFO - Dependencies all met for dep_context=non-requeueable deps ti=<TaskInstance: first_dag.Print_time manual__2023-06-18T06:06:58.286280+00:00 [queued]>
[2023-06-18T06:07:01.014+0000] {taskinstance.py:1103} INFO - Dependencies all met for dep_context=requeueable deps ti=<TaskInstance: first_dag.Print_time manual__2023-06-18T06:06:58.286280+00:00 [queued]>
[2023-06-18T06:07:01.014+0000] {taskinstance.py:1308} INFO - Starting attempt 1 of 1
[2023-06-18T06:07:01.035+0000] {taskinstance.py:1327} INFO - Executing <Task(PythonOperator): Print_time> on 2023-06-18 06:06:58.286280+00:00
[2023-06-18T06:07:01.041+0000] {standard_task_runner.py:57} INFO - Started process 390 to run task
[2023-06-18T06:07:01.045+0000] {standard_task_runner.py:84} INFO - Running: ['***', 'tasks', 'run', 'first_dag', 'Print_time', 'manual__2023-06-18T06:06:58.286280+00:00', '--job-id', '8', '--raw', '--subdir', 'DAGS_FOLDER/first_dag.py', '--cfg-path', '/tmp/tmp0sze8ktq']
[2023-06-18T06:07:01.048+0000] {standard_task_runner.py:85} INFO - Job 8: Subtask Print_time
[2023-06-18T06:07:01.070+0000] {logging_mixin.py:149} WARNING - /home/***/.local/lib/python3.7/site-packages/***/settings.py:195 DeprecationWarning: The sql_alchemy_conn option in [core] has been moved to the sql_alchemy_conn option in [database] - the old setting has been used, but please update your config.
[2023-06-18T06:07:01.126+0000] {task_command.py:410} INFO - Running <TaskInstance: first_dag.Print_time manual__2023-06-18T06:06:58.286280+00:00 [running]> on host 604c1bbb6229
[2023-06-18T06:07:01.245+0000] {taskinstance.py:1547} INFO - Exporting env vars: AIRFLOW_CTX_DAG_OWNER='***' AIRFLOW_CTX_DAG_ID='first_dag' AIRFLOW_CTX_TASK_ID='Print_time' AIRFLOW_CTX_EXECUTION_DATE='2023-06-18T06:06:58.286280+00:00' AIRFLOW_CTX_TRY_NUMBER='1' AIRFLOW_CTX_DAG_RUN_ID='manual__2023-06-18T06:06:58.286280+00:00'
[2023-06-18T06:07:01.247+0000] {taskinstance.py:1824} ERROR - Task failed with exception
Traceback (most recent call last):
  File "/home/airflow/.local/lib/python3.7/site-packages/airflow/operators/python.py", line 181, in execute
    return_value = self.execute_callable()
  File "/home/airflow/.local/lib/python3.7/site-packages/airflow/operators/python.py", line 198, in execute_callable
    return self.python_callable(*self.op_args, **self.op_kwargs)
  File "/opt/airflow/dags/first_dag.py", line 11, in get_time
    date = date.now()
UnboundLocalError: local variable 'date' referenced before assignment
[2023-06-18T06:07:01.260+0000] {taskinstance.py:1350} INFO - Marking task as FAILED. dag_id=first_dag, task_id=Print_time, execution_date=20230618T060658, start_date=20230618T060701, end_date=20230618T060701
[2023-06-18T06:07:01.275+0000] {standard_task_runner.py:109} ERROR - Failed to execute job 8 for task Print_time (local variable 'date' referenced before assignment; 390)
[2023-06-18T06:07:01.298+0000] {local_task_job_runner.py:225} INFO - Task exited with return code 1
[2023-06-18T06:07:01.328+0000] {taskinstance.py:2651} INFO - 0 downstream tasks scheduled from follow-on schedule check
